{
  "AccessGatewayFilter": "```test_results\nTest Summary:\n- TOTAL NUMBER OF TESTS EXECUTED: 19\n- PASSED: 10\n- FAILURES: 3\n- ERRORS: 6\n\n- FAIL / ERROR BREAKDOWN:\n  - Errors (6):\n    - Several tests raised AttributeError: 'dict' object has no attribute 'user' when calling get_jwt_user:\n      - test_AccessGatewayFilter (AccessGatewayFilterTest.test_AccessGatewayFilter)\n      - test_get_jwt_user_1 .. test_get_jwt_user_5 (AccessGatewayFilterTestGetJwtUser.*)\n    - Root cause (from traceback): get_jwt_user expects auth to be an object with .user and .jwt attributes but was passed a dict in these tests.\n\n  - Failures (3):\n    - test_filter_5 (AccessGatewayFilterTestFilter.test_filter_5)\n      - AssertionError: Expected True but got False.\n    - test_filter_7 (AccessGatewayFilterTestFilter.test_filter_7)\n      - AssertionError: Expected None but got False.\n    - test_filter_8 (AccessGatewayFilterTestFilter.test_filter_8)\n      - AssertionError: Expected True but got False.\n    - These failures indicate filter returned False (or unexpected value) instead of the expected results in those test cases.\n\n- SUMMARY / RECOMMENDATION:\n  - The primary implementation issue is inconsistent handling of dict vs. object types for the authorization payload:\n    - The filter method accepts request as dict or object, but get_jwt_user always treats auth as an object with attributes (.user, .jwt), leading to AttributeError when auth is a dict.\n  - To fix:\n    - Make get_jwt_user robust to dict input (extract 'user' and 'jwt' when auth is a dict), or ensure filter always passes an Authorization object to get_jwt_user.\n    - After fixing the dict/object mismatch, re-run tests â€” the three failing assertions likely relate to JWT validation/time-window logic and should be re-evaluated if they still fail.\n\nFull failing/error traces available in test output (AttributeError: 'dict' object has no attribute 'user' and assertion details).\n```",
  "AreaCalculator": "```test_results\nTest Summary:\n- TOTAL NUMBER OF TESTS EXECUTED: 26\n- PASS/FAIL COUNT FOR EACH CODE: 26 passed, 0 failed\n- SUMMARY OF ERROR MESSAGE IF ANY: No errors. All tests passed successfully.\n```",
  "ArgumentParser": "```test_results\nTest Summary:\n-TOTAL NUMBER OF TESTS EXECUTED: 21\n-PASSED: 11\n-FAILED: 10\n\n-PASS/FAIL COUNT BY TEST GROUP:\n- ArgumentParserTestAddArgument: 0 passed, 5 failed\n- ArgumentParserTestConvertType: 1 passed, 4 failed\n- ArgumentParserTestGetArgument: 5 passed, 0 failed\n- ArgumentParserTestParseArguments: 5 passed, 0 failed\n- ArgumentParserTestMain: 0 passed, 1 failed\n\n-SUMMARY OF ERRORS:\n- Many failures are AssertionError mismatches where the parser.types entries are strings like \"string\" instead of actual Python type objects (e.g. <class 'str'>). Tests expect types to be actual type objects (str, int, bool) rather than the literal strings \"string\"/\"bool\".\n  Example failing assertion: expected {'name': <class 'str'>, 'age': <class 'int'>} but got {'name': 'string', 'age': <class 'int'>}.\n\n- convert_type related failures: convert_type returns string values instead of converted Python types for some inputs. Assertions show values like '25' (string) where 25 (int) was expected, and 'True'/'False' strings where boolean True/False were expected. This indicates the type conversion path is not being invoked or not returning the expected Python types for those cases.\n\n- test_main failure mirrors the add_argument/type issue: expected types like <class 'str'> but found the string 'string' for arg2.\n\n- The stderr/stdout from the test run includes detailed tracebacks for each failing test (AssertionError) and shows there are 10 failing tests total.\n\nSuggested areas to fix:\n1. Ensure add_argument stores actual Python type objects (e.g. str, int, bool) in self.types, not the literal strings like \"string\".\n2. Align type registration and conversion so convert_type looks up converters based on stored type objects (or map the string names to actual types consistently) and returns converted Python values (int, bool) rather than their string representations.\n\n```",
  "ArrangementCalculator": "```test_results\nTest Summary:\n-TOTAL NUMBER OF TESTS EXECUTED: 27\n-PASS/FAIL COUNT FOR ArrangementCalculator: 27 passed, 0 failed\n-SUMMARY OF ERROR MESSAGE IF ANY: None. All tests passed successfully.\n```",
  "AssessmentSystem": "```test_results\nTest Summary:\n- Total number of tests executed: 31\n- Passed: 24\n- Failed: 6\n- Errors: 1\n\nFailed tests:\n- test_add_student\n- test_add_student_2\n- test_add_student_3\n- test_add_student_4\n- test_add_student_5\n- test_main\n\nError test:\n- test_get_course_average_2\n\nSummary of failure/error messages:\n- The add_student-related failures indicate a mismatch in the expected student record structure: tests expect each student's dict to include a 'name' key (e.g. {'name': 'Alice', 'grade': 3, 'major': 'Mathematics', 'courses': {}}) but the implementation stores students without the 'name' field (currently {'grade': 3, 'major': 'Mathematics', 'courses': {}}). This causes multiple assertion failures in the add_student tests and also one failure in test_main where the overall students dict is compared.\n\n- The error in test_get_course_average_2 is a TypeError:\n  \"unsupported operand type(s) for +=: 'int' and 'NoneType'\"\n  This indicates get_course_average attempted to add a None value to an int when accumulating course scores (i.e., some student's course score is None). The method does not guard against None scores before summing.\n\nNotes / suggestions:\n- add_student should include the 'name' key inside the stored student dictionary if tests expect it.\n- get_course_average should handle or skip None course scores (or tests should not insert None), to avoid TypeError when summing.\n\n```",
  "AutomaticGuitarSimulator": "```test_results\nTest Summary:\n-TOTAL NUMBER OF TESTS EXECUTED: 15\n-PASSED: 13\n-FAILED: 2\n\n-Failing tests and brief summaries:\n1) test_interpret_6 (__main__.AutomaticGuitarSimulatorTestInterpret.test_interpret_6)\n   - AssertionError: expected [{ 'Chord': '', 'Tune': ''}, { 'Chord': '', 'Tune': ''}] but got [{ 'Chord': '', 'Tune': ''}]\n   - Meaning: the test expected two empty PlayItem dicts but the implementation returned only one for the given input (mismatch in handling multiple empty/whitespace segments).\n\n2) test_interpret_9 (__main__.AutomaticGuitarSimulatorTestInterpret.test_interpret_9)\n   - AssertionError: expected None but got [{ 'Chord': '', 'Tune': ''}]\n   - Meaning: the test expected interpret(...) to return None for that input case, but the implementation returned a list with a single empty PlayItem dict.\n\n-Stdout captured from the test run:\nNormal Guitar Playing -- Chord: C, Play Tune: 53231323\nTEST_FAIL\n\n-Overall result: 13 tests passed, 2 tests failed. The failures indicate incorrect handling of certain empty/whitespace or special input cases in interpret().\n```",
  "AvgPartition": "```test_results\nTest Summary:\n-TOTAL NUMBER OF TESTS EXECUTED: 11\n-PASS/FAIL COUNT FOR EACH CODE: AvgPartition - 11 passed, 0 failed\n-SUMMARY OF ERROR MESSAGE IF ANY: None (all tests passed)\n```",
  "BalancedBrackets": "```test_results\nTest Summary:\n-TOTAL NUMBER OF TESTS EXECUTED: 15\n-PASS/FAIL COUNT FOR EACH CODE: 15 passed, 0 failed\n-SUMMARY OF ERROR MESSAGE IF ANY: No errors. All tests passed successfully.\n```",
  "BankAccount": "```test_results\nTest Summary:\n-TOTAL NUMBER OF TESTS EXECUTED: 22\n-PASS/FAIL COUNT FOR EACH CODE:\n-BankAccount: 22 passed, 0 failed\n-SUMMARY OF ERROR MESSAGE IF ANY: None (all tests passed successfully)\n```",
  "BigNumCalculator": "```test_results\nTest Summary:\n-TOTAL NUMBER OF TESTS EXECUTED: 17\n-PASS/FAIL COUNT FOR EACH CODE:\n  - add: 5 passed, 0 failed\n  - subtract: 5 passed, 0 failed\n  - multiply: 6 passed, 0 failed\n  - main (integration/basic run): 1 passed, 0 failed\n-SUMMARY OF ERROR MESSAGE IF ANY:\n  - No errors. All tests passed (OK).\n```",
  "BinaryDataProcessor": "```test_results\nTest Summary:\n-TOTAL NUMBER OF TESTS EXECUTED: 21\n-PASS/FAIL COUNT FOR EACH CODE: 21 passed / 0 failed\n-SUMMARY OF ERROR MESSAGE IF ANY: None (all tests passed)\n```",
  "BitStatusUtil": "```test_results\nTest Summary:\n- TOTAL NUMBER OF TESTS EXECUTED: 21\n- BitStatusUtil: 20 passed, 0 failed, 1 error\n\nSUMMARY OF ERROR:\n- Failing test: test_check (__main__.BitStatusUtilTestCheck.test_check)\n- Exception: ValueError\n- Message: \"Arguments should not be passed as lists. Pass them as individual integers.\"\n- Trace excerpt: File \"...tmpwz28wtn6.py\", line 101, in test_check -> bit_status_util.check([2])\n  Raised at File \"...tmpwz28wtn6.py\", line 23, in check -> raise ValueError(\"Arguments should not be passed as lists. Pass them as individual integers.\")\n- Notes: One test raised an unexpected ValueError when calling check([2]), causing an error (not a test failure). All other tests passed.\n```",
  "BlackjackGame": "```test_results\nTest Summary:\n-TOTAL NUMBER OF TESTS EXECUTED: 18\n-PASS/FAIL/ERROR COUNT: Passed: 17, Failed: 0, Errors: 1\n\n-SUMMARY OF ERROR MESSAGE:\n  Test that failed: test_calculate_hand_value_6\n  Exception: ValueError: invalid literal for int() with base 10: 'B'\n  Trace location: calculate_hand_value -> value += int(rank)\n  Explanation: The test provided a card whose rank parsed to 'B', which is not handled by the method. The code attempts int(rank) for any rank not equal to 'A', 'J', 'Q', or 'K', causing a ValueError for unexpected non-numeric ranks.\n\n-RECOMMENDATION:\n  Ensure calculate_hand_value validates the rank before converting to int (e.g., check rank.isdigit() or check membership in an explicit ranks list), or raise a clear error for unknown ranks. This will prevent the ValueError seen in test_calculate_hand_value_6 and make the function more robust.\n```",
  "BookManagement": "```test_results\nTest Summary:\n-TOTAL NUMBER OF TESTS EXECUTED: 21\n-PASS/FAIL COUNT FOR EACH CODE:\n- BookManagement: Passed 21, Failed 0\n-SUMMARY OF ERROR MESSAGE IF ANY:\n- No errors. All tests passed (OK).\n```",
  "BookManagementDB": "```test_results\nTest Summary:\n-TOTAL NUMBER OF TESTS EXECUTED: 7\n-PASSED: 6\n-FAILED: 1\n\n-Passed tests:\n - test_borrow_book (__main__.BookManagementDBTestBorrowBook.test_borrow_book)\n - test_create_table_1 (__main__.BookManagementDBTestCreateTable.test_create_table_1)\n - test_create_table_2 (__main__.BookManagementDBTestCreateTable.test_create_table_2)\n - test_remove_book (__main__.BookManagementDBTestRemoveBook.test_remove_book)\n - test_return_book (__main__.BookManagementDBTestReturnBook.test_return_book)\n - test_search_books (__main__.BookManagementDBTestSearchBooks.test_search_books)\n\n-Failed tests and error summary:\n - test_add_book (__main__.BookManagementDBTestAddBook.test_add_book)\n   AssertionError: unexpectedly None\n   Context: The test expected a non-None result (likely an inserted-row id or confirmation) from add_book, but add_book returned None. Trace excerpt:\n   File \".../tmpichyirc2.py\", line 124, in test_add_book\n     self.assertIsNotNone(result)\n   This indicates add_book does not return a value the test expects.\n\n-Suggested cause:\n - The add_book method performs the INSERT but does not return the newly inserted row id (cursor.lastrowid) or any value. The unit test expects a non-None return value.\n\n```",
  "BoyerMooreSearch": "```test_results\nTest Summary:\n-TOTAL NUMBER OF TESTS EXECUTED: 16\n-PASS/FAIL COUNT FOR EACH CODE:\n -BoyerMooreSearch: 16 passed, 0 failed\n-SUMMARY OF ERROR MESSAGE IF ANY:\n -No errors. All tests passed (output: \"OK\").\n```",
  "Calculator": "```test_results\nTest Summary:\n-TOTAL NUMBER OF TESTS EXECUTED: 0 (test run failed before tests could execute)\n-PASS/FAIL COUNT FOR Calculator: 0 passed, 0 failed\n-SUMMARY OF ERROR MESSAGE IF ANY:\n ModuleNotFoundError: No module named 'translation'\n Traceback indicates the test harness attempted to import translation.solution_py.Calculator but the expected package/module path was not found. Ensure the translated code is provided at the expected import path or update the test harness to import the Calculator class directly.\n```",
  "CalendarUtil": "```test_results\nTest Summary:\n-TOTAL NUMBER OF TESTS EXECUTED: 1\n-PASS/FAIL COUNT FOR EACH CODE:\n  - CalendarUtil: 0 passed, 1 failed\n-SUMMARY OF ERROR MESSAGE IF ANY:\n  - Test run failed during import with ModuleNotFoundError: No module named 'translation'\n  - Full stderr: Traceback (most recent call last):\n    File \"...\", line 64, in <module>\n      from translation.solution_py.CalendarUtil import CalendarUtil\n    ModuleNotFoundError: No module named 'translation'\n```",
  "ChandrasekharSieve": "```test_results\nTest Summary:\n-TOTAL NUMBER OF TESTS EXECUTED: 11\n-PASS/FAIL COUNT FOR EACH CODE: PASS: 11 / FAIL: 0\n-SUMMARY OF ERROR MESSAGE IF ANY: None â€” all tests passed successfully.\n```",
  "Chat": "```test_results\nTest Summary:\n-TOTAL NUMBER OF TESTS EXECUTED: 22\n-PASSED: 19\n-FAILED: 3\n\n-FAILED TESTS:\n- test_main (__main__.ChatTestMain.test_main)\n- test_main_2 (__main__.ChatTestMain.test_main_2)\n- test_send_message (__main__.ChatTestSendMessage.test_send_message)\n\n-SUMMARY OF ERROR MESSAGES:\n- Failures show assertion mismatches where chat.users contains Chat.Message objects but the tests expect dictionaries representing messages. Example messages from the test run:\n  - AssertionError showing left side contains <__main__.Chat.Message object at 0x...> while the right side is a dict like {'sender': 'John', 'receiver': 'Mary', 'message': 'Hello', 'timestamp': timestamp}\n  - The failing stack traces point to assertions comparing chat.users directly to a mapping of lists of dicts.\n\n-ROOT CAUSE (concise):\n- The implementation stores instances of Chat.Message in users' message lists. Tests expect plain dicts (or dict-like representations) for messages when comparing chat.users.\n\n-RECOMMENDATION:\n- Return or store message data as dicts (e.g., message_info = {'sender': ..., 'receiver': ..., 'message': ..., 'timestamp': ...}) or add a to_dict() method and ensure comparisons use that representation (or implement __eq__ / __repr__ on Message to match expected dict structure).\n\n```",
  "ClassRegistrationSystem": "```test_results\nTest Summary:\n-TOTAL NUMBER OF TESTS EXECUTED: 16\n-PASSED: 7\n-FAILED/ERRORS: 9\n\n-PASS/FAIL BREAKDOWN BY TEST GROUP:\n- General test: 1 passed, 0 failed\n- register_student tests: 3 passed, 0 failed\n- register_class tests: 3 passed, 0 failed\n- get_students_by_major tests: 0 passed, 4 failed\n- get_all_major tests: 0 passed, 3 failed\n- get_most_popular_class_in_major tests: 0 passed, 2 failed\n\n-SUMMARY OF ERROR MESSAGES:\nAll failures raised the same error type:\n- AttributeError: 'dict' object has no attribute 'get_major'\n\nThis occurred when the following methods iterated over self.students expecting Student instances:\n- get_students_by_major (errors in tests: test_get_students_by_major, test_get_students_by_major2, test_get_students_by_major3, test_get_students_by_major4)\n- get_all_major (errors in tests: test_get_all_major, test_get_all_major2, test_get_all_major3)\n- get_most_popular_class_in_major (errors in tests: test_get_most_popular_class_in_major, test_get_most_popular_class_in_major2)\n\nStack traces indicate the code encountered plain dict objects inside self.students (so student.get_major() or student.get_name() calls failed). Likely cause: some tests populate self.students with dictionaries rather than Student objects, and the methods do not handle dict entries when iterating over self.students.\n\n```",
  "Classroom": "```test_results\nTest Summary:\n- Program key: Classroom\n- Total number of tests executed: 24\n- Passed: 24\n- Failed: 0\n- Result: PASS\n- Summary of errors: None (all tests passed; no error messages or tracebacks)\n```",
  "CombinationCalculator": "```test_results\nTest Summary:\n-TOTAL NUMBER OF TESTS EXECUTED: 26\n-PASS/FAIL COUNT FOR EACH CODE: PASS 26 / FAIL 0\n-SUMMARY OF ERROR MESSAGE IF ANY: None â€” all tests passed successfully.\n```",
  "ComplexCalculator": "```test_results\nTest Summary:\n-TOTAL NUMBER OF TESTS EXECUTED\n21\n-PASS/FAIL COUNT FOR EACH CODE\nPASS: 21\nFAIL: 0\n-SUMMARY OF ERROR MESSAGE IF ANY\nNo errors. All tests passed successfully.\n```",
  "CookiesUtil": "```test_results\nTest Summary:\n-TOTAL NUMBER OF TESTS EXECUTED: 19\n-PASS/FAIL COUNT FOR EACH CODE: 19 passed, 0 failed\n\n-SUMMARY OF ERROR MESSAGE IF ANY:\n  - During tests, two error lines were printed to stderr but did not cause test failures:\n    1) \"Error: The file  does not exist.\" â€” emitted in test_load_cookies_6 (empty cookies_file path).\n    2) \"Error writing JSON file: [Errno 2] No such file or directory: ''\" â€” emitted in test_save_cookies_6 (empty cookies_file path).\n  Both messages indicate operations against an empty filename and were handled by the code's exception handlers.\n```",
  "CSVProcessor": "```test_results\nTest Summary:\n-TOTAL NUMBER OF TESTS EXECUTED: 17\n-PASS/FAIL COUNT:\n  - read_csv tests: 5 passed, 0 failed\n  - write_csv tests: 6 passed, 0 failed\n  - process_csv_data tests: 0 passed, 5 failed\n  - main test: 0 passed, 1 failed\n  - Overall: 11 passed, 6 failed\n\n-SUMMARY OF ERROR MESSAGE(S):\n  Failing tests:\n  - test_main (__main__.CSVProcessorTestMain.test_main)\n  - test_process_csv_data_1 .. test_process_csv_data_5\n\n  All failing assertions are list-equality failures where the expected header/column list contains a single element (the target column), but the actual data read back from the produced file contains multiple elements (the full row). Example assertion failure:\n    AssertionError: Lists differ: ['HELLO', 'YoU', 'ME', 'LoW'] != ['HELLO']\n\n  Likely root cause:\n  - process_csv_data currently uppercases the specified column in-place but writes the entire rows back to the output file. The tests expect the output file to contain only the selected column (header + values) as a single-column CSV. Thus the produced files contain full rows instead of only the processed column, causing the list mismatches.\n\nSuggested fix:\n  - In process_csv_data, build output rows that contain only the N-th column (and header should be the N-th title entry), e.g.:\n      header_col = title[N] (or [title[N]])\n      output_rows = [[row[N]] for row in data]\n    Then call write_csv([ [header_col] ] + output_rows, new_file_name)\n  - Ensure index bounds checks consider title length and that rows shorter than N are handled consistently.\n\n```",
  "CurrencyConverter": "```test_results\nTest Summary:\n- TOTAL NUMBER OF TESTS EXECUTED: 24\n- PASS/FAIL COUNT FOR CurrencyConverter: Passed 24, Failed 0\n- SUMMARY OF ERROR MESSAGE IF ANY: No errors. All tests passed successfully.\n```",
  "DatabaseProcessor": "```test_results\nTest Summary:\n-TOTAL NUMBER OF TESTS EXECUTED\n0\n-PASS/FAIL COUNT FOR EACH CODE\nPASS: 0\nFAIL: 0\n-SUMMARY OF ERROR MESSAGE IF ANY\nNo tests were executed; test harness reported OK with no errors.\n```",
  "DataStatistics": "```test_results\nTest Summary:\n-TOTAL NUMBER OF TESTS EXECUTED: 16\n-PASS/FAIL COUNT FOR EACH CODE: All tests passed (16 passed, 0 failed)\n-SUMMARY OF ERROR MESSAGE IF ANY: No errors. All tests returned OK.\n```",
  "DataStatistics2": "```test_results\nTest Summary:\n-TOTAL NUMBER OF TESTS EXECUTED: 31\n-DataStatistics2: 31 passed, 0 failed\n-SUMMARY OF ERROR MESSAGE IF ANY: None (all tests passed successfully)\n```",
  "DataStatistics4": "```test_results\nTest Summary:\n-TOTAL NUMBER OF TESTS EXECUTED: 21\n-PASS: 21\n-FAIL: 0\n-SUMMARY OF ERROR MESSAGE IF ANY: None (all tests passed successfully)\n```",
  "DecryptionUtils": "```test_results\nTest Summary:\n-TOTAL NUMBER OF TESTS EXECUTED: 19\n-PASS/FAIL COUNT FOR EACH CODE: All tests passed (19 passed, 0 failed)\n-SUMMARY OF ERROR MESSAGE IF ANY: No errors. All tests reported OK.\n```",
  "DiscountStrategy": "```test_results\nTest Summary:\n-TOTAL NUMBER OF TESTS EXECUTED: 26\n-PASS/FAIL COUNT:\n  - PASSED: 10\n  - ERRORS: 16\n-TESTS WITH ERRORS:\n  - test_DiscountStrategy\n  - test_bulk_item_promo_1\n  - test_bulk_item_promo_2\n  - test_bulk_item_promo_3\n  - test_bulk_item_promo_4\n  - test_bulk_item_promo_5\n  - test_fidelity_promo_1\n  - test_fidelity_promo_2\n  - test_fidelity_promo_3\n  - test_fidelity_promo_4\n  - test_fidelity_promo_5\n  - test_large_order_promo_1\n  - test_large_order_promo_2\n  - test_large_order_promo_3\n  - test_large_order_promo_4\n  - test_large_order_promo_5\n-SUMMARY OF ERROR MESSAGE:\n  All 16 failing tests raise the same TypeError:\n  \"TypeError: DiscountStrategy.promotion() takes 1 positional argument but 2 were given\"\n  The traceback shows the tests call order.promotion(order), i.e. passing an Order instance explicitly to promotion. The implemented promotion is an instance method expecting only self (no explicit order parameter), causing the signature mismatch.\n```",
  "EightPuzzle": "```test_results\nTest Summary:\n-TOTAL NUMBER OF TESTS EXECUTED: 21\n-PASS: 17\n-FAIL: 4\n-FAILED TESTS:\n  - test_find_blank_3: expected None but got (-1, -1)\n  - test_find_blank_4: expected None but got (-1, -1)\n  - test_find_blank_5: expected None but got (-1, -1)\n  - test_solve_6: expected None but got []\n-SUMMARY OF ERROR MESSAGE IF ANY:\n  - find_blank failures: AssertionError showing (-1, -1) != None â€” the find_blank method returns (-1, -1) when the blank tile isn't found, while the tests expect None in that case.\n  - solve failure: AssertionError showing [] != None â€” the solve method returns an empty list when it does not find a solution (or when initialState is not set), while the test expects None.\n```",
  "EmailClient": "```test_results\nTest Summary:\n-TOTAL NUMBER OF TESTS EXECUTED: 26\n-PASS/FAIL COUNT FOR EACH CODE:\n -EmailClient: 25 passed, 1 failed\n\n-SUMMARY OF ERROR MESSAGE IF ANY:\n -Failing test: test_clear_inbox_2 (__main__.EmailClientTestClearInbox.test_clear_inbox_2)\n -AssertionError: Lists differ: [{'size': 15}] != [{'size': 10}, {'size': 20}, {'size': 15}]\n   First differing element 0:\n   {'size': 15}\n   {'size': 10}\n   Expected inbox: [{'size': 10}, {'size': 20}, {'size': 15}]\n   Actual inbox:   [{'size': 15}]\n -Context: The test expected clear_inbox to remove enough emails to free space but leave earlier emails intact; actual behavior removed more emails (only the last email remained). Overall test run result: FAIL (1 failure).\n```",
  "EncryptionUtils": "```test_results\nTest Summary:\n-TOTAL NUMBER OF TESTS EXECUTED: 18\n-PASS/FAIL COUNT FOR EACH CODE:\n  - caesar_cipher: 6 executed, 6 passed, 0 failed\n  - vigenere_cipher: 5 executed, 4 passed, 1 failed\n  - rail_fence_cipher: 6 executed, 6 passed, 0 failed\n  - main/test_main: 1 executed, 1 passed, 0 failed\n-OVERALL: 18 executed, 17 passed, 1 failed\n\n-SUMMARY OF ERROR MESSAGE:\n  Failure occurred in test_vigenere_cipher_4.\n  Assertion:\n    Expected: \"Rijvs, Uyvjn! 123\"\n    Actual:   \"Rijvs, Ambpb! 123\"\n  Observed problem: The vigenere_cipher output is incorrect for the substring after non-letter characters (\"World\" -> produced \"Ambpb\" instead of \"Uyvjn\").\n\n-PROBABLE CAUSE / NOTES:\n  The vigenere_cipher implementation uses enumerate(index) over the entire plaintext when selecting key characters (key index = i % key_length). This advances the key position for non-alphabet characters as well, while the expected behavior (per tests) is to advance the key only when encountering alphabetic characters. As a result, key alignment is incorrect after punctuation/whitespace, producing the failing output.\n\n-SUGGESTED FIX:\n  Use a separate key index that is incremented only when an alphabetic character is processed (i.e., do not use the plaintext index directly to pick key letters). After this change, the failing test should pass.\n```",
  "ExcelProcessor": "```test_results\nTest Summary:\n- TOTAL NUMBER OF TESTS EXECUTED: 19\n- PASSED: 2\n- FAILED: 5\n- ERRORED: 12\n\nSummary of errors and failures:\n- Many tests errored with NameError: name 'openpyxl' is not defined (tests attempt to use openpyxl directly).\n- Pandas operations printed: \"Error writing file: No module named 'openpyxl'\" indicating the openpyxl dependency is missing, causing write operations to return 0.\n- Failures are assertions expecting successful writes but received 0 (write_excel returned 0) due to the missing openpyxl dependency.\n\nPrimary cause:\n- The environment lacks the openpyxl module, causing both read and write Excel operations to fail and leading to multiple test errors and write-related assertion failures.\n\nSuggested fix:\n- Install the openpyxl package (e.g., pip install openpyxl) or adjust the code/tests to not require openpyxl.\n```",
  "ExpressionCalculator": "```test_results\nTest Summary:\n-TOTAL NUMBER OF TESTS EXECUTED: 37\n-PASSED: 30\n-FAILED: 0\n-ERRORS: 7\n\n-PASS/FAIL/ERROR COUNT FOR THIS CODE (ExpressionCalculator):\n- Passed: 30\n- Failed: 0\n- Errored: 7\n\n-SUMMARY OF ERRORS:\nAll 7 errors are NameError exceptions indicating that 'Decimal' is not defined in the test module. The failing tests are:\n- test_ExpressionCalculator (__main__.ExpressionCalculatorTest.test_ExpressionCalculator)\n- test_calculate_method_1 (__main__.ExpressionCalculatorTestCalculateMethod.test_calculate_method_1)\n- test_calculate_method_2 (__main__.ExpressionCalculatorTestCalculateMethod.test_calculate_method_2)\n- test_calculate_method_3 (__main__.ExpressionCalculatorTestCalculateMethod.test_calculate_method_3)\n- test_calculate_method_4 (__main__.ExpressionCalculatorTestCalculateMethod.test_calculate_method_4)\n- test_calculate_method_5 (__main__.ExpressionCalculatorTestCalculateMethod.test_calculate_method_5)\n- test_calculate_method_6 (__main__.ExpressionCalculatorTestCalculateMethod.test_calculate_method_6)\n\n-ERROR MESSAGE (representative):\nNameError: name 'Decimal' is not defined\n\n-ADDITIONAL NOTES:\nMost other unit tests passed (including prepare, transform, is_operator, compare, and several calculate cases). The remaining errors appear to be due to the test code expecting Decimal to be available; importing or defining Decimal in the test environment (from decimal import Decimal) or adjusting the tests would resolve these NameError errors.\n```",
  "FitnessTracker": "```test_results\nTest Summary:\n-TOTAL NUMBER OF TESTS EXECUTED: 16\n-PASS/FAIL COUNT:\n  - Passed: 10\n  - Failed/Errored: 6\n\n-Failing tests (names and error summary):\n  - test_get_BMI (__main__.FitnessTrackerTestGetBMI.test_get_BMI)\n  - test_get_BMI_2 (__main__.FitnessTrackerTestGetBMI.test_get_BMI_2)\n  - test_get_BMI_3 (__main__.FitnessTrackerTestGetBMI.test_get_BMI_3)\n  - test_get_BMI_4 (__main__.FitnessTrackerTestGetBMI.test_get_BMI_4)\n  - test_get_BMI_5 (__main__.FitnessTrackerTestGetBMI.test_get_BMI_5)\n  - test_main (__main__.FitnessTrackerTestMain.test_main)\n\n  Error message for all failures:\n  AttributeError: 'FitnessTracker' object has no attribute 'get_BMI'\n\n-SUMMARY / ROOT CAUSE:\n  The tests expect a method named get_BMI (camel-case). The translated code defines get_bmi (lowercase). This name mismatch causes AttributeError when tests call get_BMI. Other functionality (condition_judge and calculate_calorie_intake tests) passed.\n\n-SUGGESTED FIX:\n  Add a get_BMI method (alias) that calls the existing get_bmi method, or rename get_bmi to get_BMI. Example fix:\n    def get_BMI(self):\n        return self.get_bmi()\n\nAfter applying that change, re-run the test suite to confirm all tests pass.\n```",
  "GomokuGame": "```test_results\nTest Summary:\n-TOTAL NUMBER OF TESTS EXECUTED: 16\n-PASS/FAIL COUNT FOR EACH CODE: PASS: 16 / FAIL: 0\n-SUMMARY OF ERROR MESSAGE IF ANY: None (all tests passed)\n```",
  "Hotel": "```test_results\nTest Summary:\n-TOTAL NUMBER OF TESTS EXECUTED: 0 (test harness failed before running tests)\n-PASS/FAIL COUNT FOR EACH CODE:\n - Hotel: 0 passed, 0 failed (no tests executed)\n-SUMMARY OF ERROR MESSAGE:\n The test runner failed with a ModuleNotFoundError before any tests could run:\n ModuleNotFoundError: No module named 'translation'\n Full stderr:\n Traceback (most recent call last):\n   File \"C:\\Users\\User\\AppData\\Local\\Temp\\tmpwz5jg2cd.py\", line 84, in <module>\n     from translation.solution_py.Hotel import Hotel\n ModuleNotFoundError: No module named 'translation'\n```",
  "HRManagementSystem": "```test_results\nTest Summary:\n-TOTAL NUMBER OF TESTS EXECUTED: 28\n-PASS: 24\n-FAIL: 4\n-FAIL COUNT FOR PROGRAM (HRManagementSystem): 4\n\n-Failed tests:\n- test_get_employee_2\n- test_get_employee_3\n- test_main\n- test_main_2\n\n-SUMMARY OF ERROR MESSAGE:\nAll failures are AssertionError where tests expected get_employee(...) to return False for missing/nonexistent employee IDs but the implementation returned None.\nExample message seen in failures: \"AssertionError: None != False\"\n```",
  "Interpolation": "```test_results\nTest Summary:\n-TOTAL NUMBER OF TESTS EXECUTED: 13\n-PASS/FAIL COUNT: 11 passed, 0 failed, 2 errors\n\n-Failing tests (errors = 2):\n  1) test_interpolate_1d_6\n     Error: ValueError: Invalid input: x, y must be non-empty and of the same length, x_interp must be non-empty.\n     Context: call was interpolate_1d([1, 6, 4], [1, 7, 5], []) â€” test expected [] but code raised ValueError when x_interp is empty.\n\n  2) test_interpolate_1d_7\n     Error: ValueError: Invalid input: x, y must be non-empty and of the same length, x_interp must be non-empty.\n     Context: call was interpolate_1d([], [], [[], []]) â€” test expected [] but code raised ValueError due to empty x/y.\n\nSUMMARY OF ERROR MESSAGES:\n-Both errors are ValueError raised by interpolate_1d with message:\n \"Invalid input: x, y must be non-empty and of the same length, x_interp must be non-empty.\"\n-Root cause: input validation in interpolate_1d rejects empty x, y, or x_interp, whereas the corresponding tests expect the function to return an empty list for those edge cases.\n\n```",
  "IPAddress": "```test_results\nTest Summary:\n-TOTAL NUMBER OF TESTS EXECUTED: 16\n-PASS/FAIL COUNT FOR EACH CODE: IPAddress: 16 passed, 0 failed\n-SUMMARY OF ERROR MESSAGE IF ANY: None (all tests passed)\n```",
  "IpUtil": "```test_results\nTest Summary:\n-TOTAL NUMBER OF TESTS EXECUTED: 0 (test run failed before executing any tests)\n\n-PASS/FAIL COUNT FOR EACH CODE:\n  - Program key: IpUtil\n    - Passed: 0\n    - Failed: 0 (tests not executed due to setup/import error)\n\n-SUMMARY OF ERROR MESSAGE:\n  The test harness failed to import the test module, so no tests were executed. Error from test runner:\n\n  ModuleNotFoundError: No module named 'translation'\n\n  Full stderr:\n  Traceback (most recent call last):\n    File \"C:\\\\Users\\\\User\\\\AppData\\\\Local\\\\Temp\\\\tmp9u81jk1j.py\", line 44, in <module>\n      from translation.solution_py.IPUtil import IpUtil\n  ModuleNotFoundError: No module named 'translation'\n\nNotes / Next steps:\n- The import path expected by the test harness is 'translation.solution_py.IPUtil'. Ensure the translated code is placed or packaged under that module path, or adjust the test harness to import the provided module directly.\n- After fixing the import/path issue, re-run the tests to get actual pass/fail counts and any error traces from the code itself.\n```",
  "JobMarketplace": "```test_results\nTest Summary:\n-TOTAL NUMBER OF TESTS EXECUTED: 36\n-PASS/FAIL COUNT FOR JobMarketplace: 33 passed / 3 failed\n\n-SUMMARY OF FAILURES:\n1) test_matches_requirements_5 (JobMarketplaceTestMatchesRequirements)\n   - Failure: AssertionError: expected False but got True\n   - Details: matches_requirements returned True for input resume dict {\"name\": \"Tom\", \"skills\": ['skill1', 'skill2'], \"experience\": \"experience\"} with requirements ['skill1']. The test expected False.\n\n2) test_remove_job_4 (JobMarketplaceTestRemoveJob)\n   - Failure: AssertionError: job_listings is [] but expected [{'job_title': 'Software Engineer', 'company': 'ABC Company', 'requirements': ['requirement1','requirement2']}]\n   - Details: remove_job removed the Software Engineer job (and left no jobs), while the test expected that job to remain.\n\n3) test_remove_job_5 (JobMarketplaceTestRemoveJob)\n   - Failure: AssertionError: job_listings missing the Software Engineer entry\n   - Details: After remove_job call the marketplace job_listings contained only the Mechanical Engineer job; the test expected both Mechanical and Software Engineer jobs (i.e., Software Engineer was removed unexpectedly).\n\n-STDOUT/STDERR: Tests ran and produced three failing assertions (tracebacks included in stderr). All other tests passed.\n```",
  "JSONProcessor": "```test_results\nTest Summary:\n- TOTAL NUMBER OF TESTS EXECUTED: 16\n\n- PASS/FAIL COUNT FOR EACH COMPONENT:\n  - read_json: 5 passed, 0 failed\n  - write_json: 5 passed, 0 failed\n  - process_json: 5 passed, 0 failed\n  - overall/main: 1 passed, 0 failed\n  - Total: 16 passed, 0 failed\n\n- SUMMARY OF ERROR MESSAGE IF ANY:\n  - No errors. All tests passed (OK).\n```",
  "LongestWord": "```test_results\nTest Summary:\n-TOTAL NUMBER OF TESTS EXECUTED: 10\n-PASS/FAIL COUNT FOR EACH CODE: PASS: 10, FAIL: 0\n-SUMMARY OF ERROR MESSAGE IF ANY: No errors. All tests passed successfully.\n```",
  "MahjongConnect": "```test_results\nTest Summary:\n- TOTAL NUMBER OF TESTS EXECUTED: 28\n- PASS/FAIL COUNT FOR EACH CODE: MahjongConnect: 28 passed, 0 failed\n- SUMMARY OF ERROR MESSAGE IF ANY: No errors; all tests passed successfully.\n```",
  "Manacher": "```test_results\nTest Summary:\n-TOTAL NUMBER OF TESTS EXECUTED: 11\n-PASSED: 5\n-FAILED: 6\n\n-PASS/FAIL COUNT FOR 'Manacher':\n  - Passed: 5\n  - Failed: 6\n\n-SUMMARY OF FAILURES:\n  1) test_main (__main__.ManacherTestMain.test_main)\n     - AssertionError: expected 'ababa' but got 'abab'\n\n  2) test_palindromic_string (__main__.ManacherTestPalindromicString.test_palindromic_string)\n     - AssertionError: expected 'ababa' but got 'abab'\n\n  3) test_palindromic_string_2 (__main__.ManacherTestPalindromicString.test_palindromic_string_2)\n     - AssertionError: expected 'ababa' but got 'abab'\n\n  4) test_palindromic_string_3 (__main__.ManacherTestPalindromicString.test_palindromic_string_3)\n     - AssertionError: expected 'ababa' but got 'abab'\n\n  5) test_palindromic_string_4 (__main__.ManacherTestPalindromicString.test_palindromic_string_4)\n     - AssertionError: expected 'ababa' but got 'abab'\n\n  6) test_palindromic_string_5 (__main__.ManacherTestPalindromicString.test_palindromic_string_5)\n     - AssertionError: expected 'aba' but got 'abab'\n\n-OBSERVATION / LIKELY CAUSE:\n  The failing tests all indicate the returned longest palindrome is missing or has an extra character (e.g., returning 'abab' instead of 'ababa' or 'aba'). This points to an off-by-one error in the index conversion from the transformed string back to the original string (calculation of start_index/end_index). The palindromic substring extraction likely needs adjustment to correctly map the centered palindrome length to original-string start/end bounds.\n```",
  "MetricsCalculator": "```test_results\nTest Summary:\n- TOTAL NUMBER OF TESTS EXECUTED: 30\n- PASSED: 30\n- FAILED: 0\n\nSummary of error messages:\n- None (all tests passed successfully)\n```",
  "MetricsCalculator2": "```test_results\nTest Summary:\n-TOTAL NUMBER OF TESTS EXECUTED: 20\n-PASS/FAIL COUNT FOR EACH CODE:\n -MetricsCalculator2Test: 4 executed â€” 2 passed, 2 failed\n -MetricsCalculator2TestMap: 8 executed â€” 3 passed, 5 failed\n -MetricsCalculator2TestMrr: 8 executed â€” 8 passed, 0 failed\n-Overall: 13 passed, 7 failed\n\n-SUMMARY OF ERROR MESSAGE IF ANY:\n Failures (test name: expected != actual):\n  - test_metricscalculator2_3: 0.41666666666666663 != 0.8333333333333333\n  - test_metricscalculator2_4: 0.3333333333333333 != 0.6666666666666666\n  - test_map_1: 0.41666666666666663 != 0.8333333333333333\n  - test_map_2: 0.0625 != 0.25\n  - test_map_3: 0.3333333333333333 != 0.6666666666666666\n  - test_map_4: 0.40625 != 0.625\n  - test_map_5: 0.3645833333333333 != 0.6527777777777777\n\nNotes:\n- All failing assertions exhibit a numeric mismatch (actual values consistently larger than expected).\n- The failures are confined to the aggregate averaging logic in map() and the outer mrr() aggregation (per-query MRR calculations themselves passed in the MRR unit tests).\n- Likely root cause: a discrepancy in how the mean is computed (denominator or which items are included when averaging). I recommend checking whether the average should be taken over all input pairs or only over the valid/positive-count entries (or if some other normalization is expected).\n\n```",
  "MovieBookingSystem": "```test_results\nTest Summary:\n- TOTAL NUMBER OF TESTS EXECUTED: 16\n- PASSED: 11\n- FAILED: 5\n\nFailed tests:\n- test_add_movie_1\n- test_add_movie_3\n- test_add_movie_4\n- test_add_movie_5\n- test_main\n\nSummary of error messages:\n- All failures show the same assertion mismatch when comparing stored movie start_time to the expected value:\n  AssertionError: datetime.time(17, 5) != datetime.datetime(1900, 1, 1, 17, 5)\n- Root cause: MovieBookingSystem.parse_time currently returns a datetime.time object (using .time()), but the tests expect a datetime.datetime object (datetime.strptime(...) without .time()).",
  "MovieTicketDB": "```test_results\nTest Summary:\n-TOTAL NUMBER OF TESTS EXECUTED: 16\n-PASS/FAIL COUNT FOR EACH CODE: MovieTicketDB - 16 passed, 0 failed\n-SUMMARY OF ERROR MESSAGE IF ANY: None (all tests passed)\n```",
  "MusicPlayer": "```test_results\nTest Summary:\n-TOTAL NUMBER OF TESTS EXECUTED: 42\n-PASSED: 39\n-FAILED: 3\n\n-Failed tests:\n  1) test_play_3\n     - Failure: AssertionError: 'song1' != False\n     - Summary: The test expected play() to return False in this scenario, but the method returned the string 'song1'. Likely mismatch between expected boolean return and current implementation returning the current song string.\n\n  2) test_set_volume4\n     - Failure: AssertionError: None != False\n     - Summary: The test expected set_volume(101) to return False for invalid volume, but the method returned None. Current implementation silently ignores invalid volumes and returns None instead of a boolean indicator.\n\n  3) test_set_volume5\n     - Failure: AssertionError: None != False\n     - Summary: Same as above for set_volume(-1) â€” expected False for invalid input, but got None.\n\n-Suggestions:\n- Adjust play() return semantics (or tests) so that the method returns False where tests expect a boolean failure instead of returning the current song string.\n- Modify set_volume() to return a boolean (True on success, False on invalid input) rather than returning None for invalid volumes.\n\n-Complete stderr/stdout trace available from test run for debugging if needed.\n```",
  "NLPDataProcessor": "```test_results\nTest Summary:\n-TOTAL NUMBER OF TESTS EXECUTED: 11\n-PASS: 9\n-FAIL: 2\n\n-Failing tests and error summaries:\n1) test_construct_stop_word_list (__main__.NLPDataProcessorTestConstruct.test_construct_stop_word_list)\n   - AssertionError: expected ['a', 'an', 'the'] but got {'the', 'a', 'an'}\n   - Cause: construct_stop_word_list() returns a set, while the test expects a list (order/types mismatch).\n\n2) test_remove_stop_words_5 (__main__.NLPDataProcessorTestRemove.test_remove_stop_words_5)\n   - AssertionError: Lists differ:\n     Actual: [['test'], ['apple'], ['dog']]\n     Expected: [['is', 'test'], ['is', 'apple'], ['is', 'dog']]\n   - Cause: the token \"is\" was removed as a stop word in the actual output but the test expects \"is\" to remain.\n\n-Notes:\n  - All other tests passed (9/11).\n  - To fix failures:\n    - Return a list (with expected ordering) from construct_stop_word_list() if tests require a list.\n    - Investigate why \"is\" is being removed in test_remove_stop_words_5 (check the stop word list provided to remove_stop_words in that test or the normalization logic).\n\n```",
  "NLPDataProcessor2": "```test_results\nTest Summary:\n-TOTAL NUMBER OF TESTS EXECUTED: 16\n-PASS/FAIL COUNT FOR EACH CODE: PASS: 16 / FAIL: 0\n-SUMMARY OF ERROR MESSAGE IF ANY: No errors. All tests passed successfully.\n```",
  "NumberConverter": "```test_results\nTest Summary:\n-TOTAL NUMBER OF TESTS EXECUTED: 31\n-PASS/FAIL COUNT FOR EACH CODE: PASS: 31 / FAIL: 0\n-SUMMARY OF ERROR MESSAGE IF ANY: None (all tests passed)\n```",
  "NumberWordFormatter": "```test_results\nTest Summary:\n-TOTAL NUMBER OF TESTS EXECUTED: 28\n-PASS/FAIL COUNT FOR EACH CODE: 21 passed, 7 failed (errors)\n-SUMMARY OF ERROR MESSAGE IF ANY:\n Seven tests errored with AttributeError: 'NumberWordFormatter' object has no attribute 'format_string'.\n Failing tests:\n  - test_NumberWordFormatter\n  - test_format_string_1\n  - test_format_string_2\n  - test_format_string_3\n  - test_format_string_4\n  - test_format_string_5\n  - test_format_string_6\n\n Root cause: The tests call formatter.format_string(...), but the translated class defines a method named format(...) and no format_string method. Adding a format_string alias that calls format (or renaming the method) will resolve these errors.\n```",
  "NumericEntityUnescaper": "```test_results\nTest Summary:\n-TOTAL NUMBER OF TESTS EXECUTED: 17\n-PASS/FAIL COUNT FOR EACH CODE: PASS: 17 / FAIL: 0\n-SUMMARY OF ERROR MESSAGE IF ANY: None. All tests passed successfully.\n```",
  "Order": "```test_results\nTest Summary:\n-TOTAL NUMBER OF TESTS EXECUTED: 17\n-PASSED: 1\n-FAILURES: 1\n-ERRORS: 15\n\n-Passing test:\n - test_checkout_2 (__main__.OrderTestCheckout) ... ok\n\n-Failing test (assertion):\n - test_add_dish_6 (__main__.OrderTestAddDish) ... FAIL\n   - AssertionError: expected True but got False\n\n-Errored tests (AttributeError in add_dish):\n - test_order (__main__.OrderTest)\n - test_add_dish_1 (__main__.OrderTestAddDish)\n - test_add_dish_2 (__main__.OrderTestAddDish)\n - test_add_dish_3 (__main__.OrderTestAddDish)\n - test_add_dish_4 (__main__.OrderTestAddDish)\n - test_add_dish_5 (__main__.OrderTestAddDish)\n - test_calculate_total_1 (__main__.OrderTestCalculateTotal)\n - test_calculate_total_2 (__main__.OrderTestCalculateTotal)\n - test_calculate_total_3 (__main__.OrderTestCalculateTotal)\n - test_calculate_total_4 (__main__.OrderTestCalculateTotal)\n - test_calculate_total_5 (__main__.OrderTestCalculateTotal)\n - test_checkout_1 (__main__.OrderTestCheckout)\n - test_checkout_3 (__main__.OrderTestCheckout)\n - test_checkout_4 (__main__.OrderTestCheckout)\n - test_checkout_5 (__main__.OrderTestCheckout)\n\n-Summary of primary error message(s):\n - Most errors raised: AttributeError: 'dict' object has no attribute 'name'\n   - Occurs in Order.add_dish when the code attempts to access dish.name while dish is still a dict.\n - One test failed due to an unexpected boolean return:\n   - test_add_dish_6: AssertionError: False is not true\n\nSuggested next steps (brief):\n - Fix add_dish handling of dict input so it reliably converts the input dict to a Dish object (ensure the conversion always runs and respects the provided 'count' value).\n - Investigate logic that decides availability and return value for the scenario covered by test_add_dish_6 (expected True but returned False).\n - Re-run tests after fixes.\n\n```",
  "PageUtil": "```test_results\nTest Summary:\n-TOTAL NUMBER OF TESTS EXECUTED: 16\n-PASS/FAIL COUNT FOR EACH CODE: PASS 16 / FAIL 0\n-SUMMARY OF ERROR MESSAGE IF ANY: No errors or failures; all tests passed (Ran 16 tests, OK)\n```",
  "PersonRequest": "```test_results\nTest Summary:\n-TOTAL NUMBER OF TESTS EXECUTED: 16\n-PASS/FAIL COUNT FOR EACH CODE: PersonRequest â€” 16 passed, 0 failed\n-SUMMARY OF ERROR MESSAGE IF ANY: None (all tests passed successfully)\n```",
  "PushBoxGame": "```test_results\nTest Summary:\n-TOTAL NUMBER OF TESTS EXECUTED: 16\n-PASS/FAIL COUNT FOR EACH CODE: Passed: 16, Failed: 0\n-SUMMARY OF ERROR MESSAGE IF ANY: No errors. All tests passed (OK).\n```",
  "RegexUtils": "```test_results\nTest Summary:\n-TOTAL NUMBER OF TESTS EXECUTED: 51\n-PASS/FAIL COUNT FOR EACH CODE: 51 passed, 0 failed\n-SUMMARY OF ERROR MESSAGE IF ANY: None. All tests passed (Ran 51 tests, OK).\n```",
  "RPGCharacter": "```test_results\nTest Summary:\n-TOTAL NUMBER OF TESTS EXECUTED: 26\n-PASS/FAIL COUNT FOR RPGCharacter: 26 passed, 0 failed\n-SUMMARY OF ERROR MESSAGE IF ANY: All tests passed (OK). No error messages reported.\n```",
  "Server": "```test_results\nTest Summary:\n-TOTAL NUMBER OF TESTS EXECUTED: 26\n-PASS/FAIL COUNT FOR EACH CODE: 26 passed, 0 failed\n-SUMMARY OF ERROR MESSAGE IF ANY: No errors. All tests passed (output shows 'OK' and all individual tests reported as ok).\n```",
  "ShoppingCart": "```test_results\nTest Summary:\n-TOTAL NUMBER OF TESTS EXECUTED: 23\n-PASS: 22\n-FAIL: 1\n\n-FAILED TEST(S):\n  - test_add_item_6 (ShoppingCartTestAddItem)\n\n-SUMMARY OF ERROR MESSAGE:\n  AssertionError in test_add_item_6:\n  Expected shoppingcart.items == {\"apple\": {\"price\": 1, \"quantity\": 5}}\n  Actual shoppingcart.items == {\"apple\": {\"price\": 1, \"quantity\": 10}}\n\n  Trace excerpt:\n  File \".../tmp...py\", line 65, in test_add_item_6\n    self.assertEqual(shoppingcart.items, {\"apple\": {\"price\": 1, \"quantity\": 5}})\n  AssertionError: {'apple': {'price': 1, 'quantity': 10}} != {'apple': {'price': 1, 'quantity': 5}}\n\n-ADDITIONAL NOTES / SUGGESTED ACTION:\n  The failure indicates the ShoppingCart.add_item behavior resulted in quantity 10 for 'apple' when the test expected quantity 5. The implementation currently increments the existing item's quantity (self.items[item]['quantity'] += quantity). If the intended behavior for this test is to set/replace the quantity instead of adding to it, change the update branch to assign the provided quantity (self.items[item]['quantity'] = quantity). Otherwise, confirm the test's expected sequence of add_item calls to ensure it matches intended semantics.\n```",
  "SignInSystem": "```test_results\nTest Summary:\n-TOTAL NUMBER OF TESTS EXECUTED: 26\n-RESULTS FOR SignInSystem: 26 passed, 0 failed\n-SUMMARY OF ERROR MESSAGE IF ANY: None â€” all tests passed successfully\n```",
  "Snake": "```test_results\nTest Summary:\n-21 tests executed\n-PASS/FAIL COUNT FOR EACH CODE\n-Snake: 21 passed, 0 failed\n-SUMMARY OF ERROR MESSAGE IF ANY\n-No errors; all tests passed (OK).\n```",
  "SplitSentence": "```test_results\nTest Summary:\n-TOTAL NUMBER OF TESTS EXECUTED: 16\n-PASS/FAIL COUNT FOR EACH CODE:\n -SplitSentence: 16 passed, 0 failed\n-SUMMARY OF ERROR MESSAGE IF ANY:\n -None. All tests passed successfully.\n```",
  "SQLGenerator": "```test_results\nTest Summary:\n-TOTAL NUMBER OF TESTS EXECUTED: 32\n-PASS/FAIL COUNT FOR EACH CODE:\n - SQLGenerator: 32 passed, 0 failed\n-SUMMARY OF ERROR MESSAGE IF ANY:\n - No errors. All tests passed (Ran 32 tests â€” OK).\n```",
  "SQLQueryBuilder": "```test_results\nTest Summary:\n-TOTAL NUMBER OF TESTS EXECUTED: 25\n-PASS: 25\n-FAIL: 0\n-SUMMARY OF ERROR MESSAGE IF ANY: All tests passed; no errors or tracebacks produced.\n```",
  "StockPortfolioTracker": "```test_results\nTest Summary:\n- TOTAL NUMBER OF TESTS EXECUTED: 38\n- PASSED: 9\n- FAILURES: 3\n- ERRORS: 26\n\nFAIL/ERROR DETAILS (summary):\n- Failures (3):\n  1) test_add_stock\n     - AssertionError: expected portfolio element to be a dict ({'name': 'AAPL', 'price': 150.0, 'quantity': 10}) but actual element is a Stock object.\n  2) test_buy_stock\n     - Same assertion mismatch: portfolio contains Stock objects while expected a dict representation.\n  3) test_main\n     - Same assertion mismatch as above.\n\n- Errors (26):\n  - The majority of errors are AttributeError: 'dict' object has no attribute 'name' (or 'price'), raised when code attempts to access attributes on portfolio items that are plain dicts.\n  - Representative trace (repeated across many tests):\n    - File \"...\", in add_stock: if pf.name == stock.name: AttributeError: 'dict' object has no attribute 'name'\n  - Other errors originate from the same root cause in methods remove_stock, calculate_portfolio_value, get_portfolio_summary, sell_stock, etc., when iterating over self.portfolio and expecting objects with .name, .price, .quantity.\n\nRoot cause summary:\n- The implementation mixes two representations for stocks:\n  - The StockPortfolioTracker stores Stock instances in some flows but tests (and some code paths) expect portfolio items to be dict-like (or vice versa). This mismatch leads to:\n    - Assertion failures where tests expect dict entries in tracker.portfolio but find Stock instances.\n    - AttributeError when portfolio contains dicts and code tries to access .name/.price attributes.\n- In short: portfolio item representation is inconsistent with the tests' expectations, causing both assertion failures and AttributeErrors across many methods.\n\nIf you want, I can:\n- Propose a small set of changes to make the implementation consistently use dicts (or consistently use Stock instances) to satisfy the tests.\n- Or update the code and re-run the tests to show a passing test run.\n```",
  "StudentDatabaseProcessor": "```test_results\nTest Summary:\n-TOTAL NUMBER OF TESTS EXECUTED: 16\n-PASS/FAIL COUNT FOR EACH CODE:\n - StudentDatabaseProcessor: 16 passed, 0 failed\n-SUMMARY OF ERROR MESSAGE IF ANY:\n - None. All tests passed (stdout contained 'TEST_PASS' and the unittest run reported OK).\n```",
  "TextFileProcessor": "```test_results\nTest Summary:\n-TOTAL NUMBER OF TESTS EXECUTED: 21\n-PASS/FAIL COUNT FOR EACH CODE: PASS: 21 / FAIL: 0\n-SUMMARY OF ERROR MESSAGE IF ANY: None â€” all tests passed successfully.\n```",
  "Thermostat": "```test_results\nTest Summary:\n-TOTAL NUMBER OF TESTS EXECUTED: 36\n-PASS/FAIL COUNT FOR EACH CODE:\n Thermostat: 36 passed, 0 failed\n-SUMMARY OF ERROR MESSAGE IF ANY:\n None â€” all tests passed successfully.\n```",
  "TicTacToe": "```test_results\nTest Summary:\n-TOTAL NUMBER OF TESTS EXECUTED: 16\n-PASS/FAIL COUNT: 14 passed, 2 failed\n\n-Failed tests:\n  - test_check_winner_5\n  - test_main\n\n-SUMMARY OF ERROR MESSAGES:\n  - test_check_winner_5: AssertionError: '\\x00' != None\n    -> The test expected check_winner() to return None for no winner, but the method returned the string '\\\\0' (displayed as '\\x00').\n  - test_main: AssertionError: '\\x00' is not false\n    -> The test expected check_winner() to be falsy (False or None) in the main scenario, but received the non-empty string '\\\\0'.\n\n-Likely cause:\n  - The check_winner() method returns the string '\\\\0' when there is no winner. Tests expect a falsy value (None or False). Changing the final return from '\\\\0' to None (or False) should resolve the failures.\n```",
  "TimeUtils": "```test_results\nTest Summary:\n-TOTAL NUMBER OF TESTS EXECUTED: 36\n-PASS/FAIL COUNT FOR PROGRAM 'TimeUtils': 10 passed, 26 failed (errors)\n\n-SUMMARY OF ERROR MESSAGES:\n1) Repeated AttributeError: 'TimeUtils' object has no attribute 'datetime'\n   - Many tests expect the instance to expose a public attribute named `datetime` but the translated class stores its value in `_datetime`. This caused tests for get_current_time, get_current_date, add_seconds, datetime_to_string, and others to error out.\n\n2) NameError: name 'datetime' is not defined\n   - Several string_to_datetime tests raised NameError when the test code referenced `datetime.datetime(...)`. (This indicates the test's assertion used `datetime` but it was not defined/imported in that test context.)\n\n-ADDITIONAL NOTES / SUGGESTED FIXES:\n- Expose the internal datetime as a public attribute (e.g., set self.datetime = _dt.now() or provide a property) so tests that reference timeutils.datetime succeed.\n- After addressing the attribute naming mismatch, re-run tests; the NameError occurrences in the test output may then reveal whether any other functional issues remain.\n\n```",
  "TriCalculator": "```test_results\nTest Summary:\n-TOTAL NUMBER OF TESTS EXECUTED: 26\n-PASS/FAIL COUNT FOR EACH CODE: TriCalculator: 26 passed, 0 failed\n-SUMMARY OF ERROR MESSAGE IF ANY: No errors. All tests passed (OK). Note: stdout contains debug prints like \"Taylor result for cos: ...\" but these are not errors.\n```",
  "TwentyFourPointGame": "```test_results\nTest Summary:\n-TOTAL NUMBER OF TESTS EXECUTED: 18\n-PASS/FAIL COUNT FOR EACH CODE:\n  - TwentyFourPointGame: 18 passed, 0 failed\n-SUMMARY OF ERROR MESSAGE IF ANY:\n  - No errors. All tests passed successfully.\n```",
  "URLHandler": "```test_results\nTest Summary:\n-TOTAL NUMBER OF TESTS EXECUTED: 32\n-OVERALL PASS/FAIL: 30 passed, 2 failed\n-RESULT BY PROGRAM (URLHandler): 32 tests â€” 30 passed, 2 failed\n\n-Failing tests and error summaries:\n1) test_get_path_6 (URLHandlerTestGetPath.test_get_path_6)\n   - Failure: AssertionError: 'abcdefg' is not None\n   - Summary: The test expected get_path() to return None, but the method returned 'abcdefg'. This indicates get_path() is returning a non-None value when the URL contains only a fragment (no path/query), whereas the test expects None in that case.\n\n2) test_get_query_params_6 (URLHandlerTestGetQueryParams.test_get_query_params_6)\n   - Failure: AssertionError: None != {}\n   - Summary: The test expected get_query_params() to return an empty dict {} for a URL with no query parameters, but the method returned None. The implementation currently returns None when there are no query params; the test expects {} instead.\n\n-Additional notes:\n  - All other tests passed (including scheme, host, fragment, many path and query param cases).\n  - Full test output (including tracebacks) was produced by the test run for the two failures.\n```",
  "UrlPath": "```test_results\nTest Summary:\n-TOTAL NUMBER OF TESTS EXECUTED: 19\n-PASS/FAIL COUNT FOR EACH CODE: UrlPath: 19 passed, 0 failed\n-SUMMARY OF ERROR MESSAGE IF ANY: No errors. All tests passed successfully.\n```",
  "UserLoginDB": "```test_results\nTest Summary:\n-TOTAL NUMBER OF TESTS EXECUTED: 1\n-PASS/FAIL COUNT FOR EACH CODE:\n - UserLoginDB: 0 passed, 1 failed (1 error)\n-SUMMARY OF ERROR MESSAGE IF ANY:\n - Traceback (most recent call last):\n   File \"...\", line 112, in setUp\n     cursor.execute(create_table_query)\n   sqlite3.OperationalError: near \"CREATE\": syntax error\n```",
  "VectorUtil": "```test_results\nTest Summary:\n-TOTAL NUMBER OF TESTS EXECUTED: 22\n-PASSED: 6\n-FAILED/ERRORS: 16\n\n-PASS/FAIL COUNT BY TEST GROUP:\n  - VectorUtilTest: 0 passed, 1 error (test_vectorutil)\n  - VectorUtilTestSimilarity: 0 passed, 5 errors (test_similarity_1..5)\n  - VectorUtilTestCosineSimilarities: 0 passed, 5 errors (test_cosine_similarities_1..5)\n  - VectorUtilTestNSimilarity: 1 passed, 5 errors (test_n_similarity_1..5, test_n_similarity_6 passed)\n  - VectorUtilTestComputeIdfWeightDict: 5 passed, 0 errors (test_compute_idf_weight_dict_1..5)\n\n-SUMMARY OF ERROR MESSAGES:\n  The failing tests consistently raise:\n    NameError: name 'np' is not defined\n  This occurs in many tests where the test code uses numpy (np.array(...)) but the test environment's test file did not import numpy as np. As a result, 16 tests error out before exercising the VectorUtil functions.\n\n-IMPACT:\n  The errors appear to be in the test harness (missing import of numpy) rather than in the translated VectorUtil implementation. The compute_idf_weight_dict tests passed, indicating some parts of the implementation are correct, but most vector-related tests could not run due to the NameError.\n\n```",
  "VendingMachine": "```test_results\nTest Summary:\n-TOTAL NUMBER OF TESTS EXECUTED: 27\n-PASS/FAIL COUNT FOR EACH CODE:\n VendingMachine - Passed: 27, Failed: 0\n-SUMMARY OF ERROR MESSAGE IF ANY:\n No errors. All tests passed successfully.\n```",
  "Warehouse": "```test_results\nTest Summary:\n-TOTAL NUMBER OF TESTS EXECUTED: 32\n-PASS/FAIL COUNT FOR PROGRAM 'Warehouse': 32 passed / 0 failed\n-SUMMARY OF ERROR MESSAGES: None (all tests passed). Full test output indicates \"OK\" and 'TEST_PASS'.\n```",
  "WeatherSystem": "```test_results\nTest Summary:\n-TOTAL NUMBER OF TESTS EXECUTED: 22\n-PASSED: 16\n-ERRORS: 6\n-FAILED: 0\n\n-Tests that errored:\n - test_main (__main__.WeatherSystemTestMain.test_main)\n - test_query (__main__.WeatherSystemTestQuery.test_query)\n - test_query_3 (__main__.WeatherSystemTestQuery.test_query_3)\n - test_query_4 (__main__.WeatherSystemTestQuery.test_query_4)\n - test_query_5 (__main__.WeatherSystemTestQuery.test_query_5)\n - test_query_6 (__main__.WeatherSystemTestQuery.test_query_6)\n\n-SUMMARY OF ERROR MESSAGE:\n All errors are KeyError: 'temperature_units' raised in WeatherSystem.query when evaluating:\n    if weather_info['temperature_units'] != tmp_units:\n This indicates the weather_info dict entries provided by the tests are missing the 'temperature_units' key (or have a different structure), causing the KeyError when the code attempts to access that key.\n```",
  "Words2Numbers": "```test_results\nTest Summary:\n-TOTAL NUMBER OF TESTS EXECUTED: 0 (test run failed before executing any tests)\n-PASS/FAIL COUNT FOR EACH CODE: Words2Numbers: 0 passed, 0 tests run, overall FAIL due to test harness error\n-SUMMARY OF ERROR MESSAGE:\n  ModuleNotFoundError: No module named 'translation'\n  Full stderr trace:\n  Traceback (most recent call last):\n    File \"C:\\\\Users\\\\User\\\\AppData\\\\Local\\\\Temp\\\\tmpit3hssxt.py\", line 83, in <module>\n      from translation.solution_py.Words2Numbers import Words2Numbers\n  ModuleNotFoundError: No module named 'translation'\n\nNotes:\n- The test harness attempted to import the translated code from a package path 'translation.solution_py.Words2Numbers', which does not exist in the test environment. \n- To proceed, either adjust the test import path to use the provided class directly, or place the translated code into the expected module path so the harness can import and run the tests.\n```",
  "XMLProcessor": "```test_results\nTest Summary:\n- TOTAL NUMBER OF TESTS EXECUTED: 23\n- PASS/FAIL COUNT FOR PROGRAM 'XMLProcessor': 23 passed, 0 failed\n\n- SUMMARY OF ERROR MESSAGES (observed during tests):\n  - \"Error: Could not load XML file: \" printed during test_read_xml_6 (handled by the code when file_name is empty/missing).\n  - \"Error: No XML document to write.\" printed during test_write_xml_6 (handled by the code when root/tree is None).\n  - These error messages were emitted to stderr but were expected by the tests and did not cause any test failures.\n\nAll tests passed (OK).\n```",
  "ZipFileProcessor": "```test_results\nTest Summary:\n-TOTAL NUMBER OF TESTS EXECUTED: 25\n-PASSED: 19\n-FAILED: 0\n-ERRORS: 6\n\n-SUMMARY OF ERROR MESSAGES:\n1) AttributeError: 'ZipFileInfo' object has no attribute 'close'\n   - Occurred in:\n     - test_ZipFileProcessor\n     - test_read_zip_file_1\n     - test_read_zip_file_2\n     - test_read_zip_file_3\n     - test_read_zip_file_4\n     - test_read_zip_file_5\n   - Context: The tests expect the object returned by read_zip_file() to expose a close() method (i.e., behave like a zipfile object). The implementation returns a simple ZipFileInfo instance without a close() method.\n\n2) Printed runtime errors observed in test output (informational):\n   - \"Error creating zip file: [Errno 2] No such file or directory: ''\"\n   - \"Failed to read zip file: [Errno 2] No such file or directory: ''\"\n   - These indicate attempts to open or write ZIP files with an empty path in the test inputs.\n\nOverall result: 6 test errors (root cause primarily that read_zip_file() returns a ZipFileInfo lacking expected methods such as close()). Fixing read_zip_file() to return an open ZipFile object or to provide the expected interface should resolve the errors.\n```"
}